<?xml version="1.0" ?>
<robot name="sakura" xmlns:xacro="http://ros.org/wiki/xacro">
  <xacro:include filename="$(find tel_map)/urdf/common_properties.xacro"/>
  <xacro:include filename="$(find tel_map)/urdf/sakura.gazebo.xacro"/>

  <link name="base_footprint"/>

  <joint name="base_joint" type="fixed">
    <parent link="base_footprint"/>
    <child link="mc_base"/>
    <origin xyz="0.0 0.0 0.0" rpy="0 0 0"/>
  </joint>

  <link name="mc_base">
    <visual>
      <origin xyz="0.3 0.135 0.015" rpy="1.57079 0 -1.57079"/>
      <geometry>
        <mesh filename="package://tel_map/meshes/bases/main.stl" scale="0.001 0.001 0.001"/>
      </geometry>
      <material name="light_black"/>
    </visual>

    <collision>
      <origin xyz="0.0 0 0.07" rpy="0 0 0"/>
      <geometry>
        <box size="0.280 0.280 0.05"/>
      </geometry>
    </collision>

    <inertial>
      <origin xyz="0 0 0" rpy="0 0 0"/>
      <mass value="200.0"/>
      <inertia ixx="0.1" ixy="-0.001" ixz="0.0001"
               iyy="0.1" iyz="0.001"
               izz="0.1" />
    </inertial>
  </link>

  <!--Shovel-->>

  <joint name="shovel_joint" type="revolute">
    <parent link="base_footprint"/>
    <child link="shovel_link"/>
    <origin xyz="-0.077 0.0 0.105" rpy="0 0 0"/>
    <limit lower="-0.1" upper="3.0416" effort="50" velocity="7.5"/>
    <axis xyz="0.0 1.0 0.0"/>
  </joint>

  <link name="shovel_link">
    <visual>
      <origin xyz="0.028 0.14 0.375" rpy="3.14159 0 -1.57079"/>
      <geometry>
        <mesh filename="package://tel_map/meshes/bases/shovel.stl" scale="0.001 0.001 0.001"/>
      </geometry>
      <material name="light_black"/>
    </visual>

    <collision  name="shovel_collision1">
      <origin xyz="-0.15 0 -0.065" rpy="0 -0.16 0"/>
      <geometry>
        <box size="0.09 0.24 0.002"/>
      </geometry>
    </collision>

    <collision name="shovel_collision2">
      <origin xyz="-0.1 0 -0.035" rpy="0 -0.95 0"/>
      <geometry>
        <box size="0.05 0.24 0.002"/>
      </geometry>
    </collision>

    <inertial>
      <origin xyz="-0.1 0 0" />
      <mass value="0.1" />
      <inertia ixx="1.1175580e-05" ixy="-4.2369783e-11" ixz="-5.9381719e-09"
               iyy="1.1192413e-05" iyz="-1.4400107e-11"
               izz="2.0712558e-05" />
      </inertial>
  </link>

  <!--roller-->>

  <joint name="roller_arm_joint" type="revolute">
    <parent link="base_footprint"/>
    <child link="roller_arm_a_link"/>
    <origin xyz="-0.069 0.0 0.083" rpy="0 0 0"/>
    <limit lower="-2.0" upper="1.0" effort="50" velocity="7.5"/>
    <axis xyz="0.0 1.0 0.0"/>
  </joint>

  <link name="roller_arm_a_link">
    <visual>
      <origin xyz="-0.02 0.335 -0.005" rpy="1.57079 0 0"/>
      <geometry>
        <mesh filename="package://tel_map/meshes/bases/roller_arm_a.stl" scale="0.001 0.001 0.001"/>
      </geometry>
      <material name="light_black"/>
    </visual>

    <inertial>
      <origin xyz="0.0 0 0.1" />
      <mass value="0.1" />
      <inertia ixx="0.005" ixy="0.00005" ixz="0.00005"
               iyy="0.005" iyz="0.00005"
               izz="0.005" />
    </inertial>
  </link>

   <joint name="roller_arm_slider" type="prismatic">
    <parent link="roller_arm_a_link"/>
    <child link="roller_arm_b_link"/>
    <origin xyz="0.0 0.0 0.0" rpy="0 0 0"/>
    <limit lower="0.0" upper="0.16" effort="250.0" velocity="0.15"/>
    <axis xyz="0.0 0.0 1.0"/>
    <safety_controller k_velocity="70" k_position="50" soft_lower_limit="-10.0" soft_upper_limit="10.0" />
  </joint>

  <link name="roller_arm_b_link">
    <visual>
      <origin xyz="-0.014 0.335 0.01" rpy="1.571 0 0"/>
      <geometry>
        <mesh filename="package://tel_map/meshes/bases/roller_arm_b.stl" scale="0.001 0.001 0.001"/>
      </geometry>
      <material name="light_black"/>
    </visual>

    <inertial>
      <origin xyz="0.0 0 0.1" />
      <mass value="0.05" />
      <inertia ixx="0.005" ixy="0.00005" ixz="0.00005"
               iyy="0.005" iyz="0.00005"
               izz="0.005" />
    </inertial>
  </link>

  <joint name="roller_joint" type="continuous">
    <parent link="roller_arm_b_link"/>
    <child link="roller_link"/>
    <origin xyz="0.0 0.0 0.212" rpy="0 0 0"/>
    <limit effort="500" velocity="20000.0"/>
    <axis xyz="0.0 1.0 0.0"/>
  </joint>

  <link name="roller_link">
    <visual>
      <origin xyz="-0.0223 -0.135 -0.022" rpy="0 0 0"/>
      <geometry>
        <mesh filename="package://tel_map/meshes/bases/roller.stl" scale="0.001 0.001 0.001"/>
      </geometry>
      <material name="light_black"/>
    </visual>

    <collision>
      <origin xyz="0 0 0" rpy="1.571 0 0"/>
      <geometry>
        <cylinder length="0.24" radius="0.022"/>
      </geometry>
    </collision>

    <inertial>
      <origin xyz="-0.0 0 0" />
      <mass value="0.02" />
      <inertia ixx="1.1175580e-05" ixy="0.0" ixz="0.0"
               iyy="1.1192413e-05" iyz="0.0"
               izz="2.0712558e-05" />
    </inertial>
  </link>

<!--wheels-->

  <joint name="wheel_left_joint" type="continuous">
    <parent link="mc_base"/>
    <child link="wheel_left_link"/>
    <origin xyz="0.11 0.1 0.03" rpy="-1.57079 0 0"/>
    <axis xyz="0 0 1"/>
  </joint>

  <link name="wheel_left_link">
    <visual>
      <origin xyz="0 0 0" rpy="0 0 0"/>
      <geometry>
        <cylinder length="0.018" radius="0.03"/>
      </geometry>
      <material name="dark"/>
    </visual>

    <collision>
      <origin xyz="0 0 0" rpy="0 0 0"/>
      <geometry>
        <cylinder length="0.018" radius="0.03"/>
      </geometry>
    </collision>

    <inertial>
      <origin xyz="0 0 0" />
      <mass value="2.8498940e-02" />
      <inertia ixx="1.1175580e-05" ixy="-4.2369783e-11" ixz="-5.9381719e-09"
               iyy="1.1192413e-05" iyz="-1.4400107e-11"
               izz="2.0712558e-05" />
      </inertial>
  </link>

  <joint name="wheel_right_joint" type="continuous">
    <parent link="mc_base"/>
    <child link="wheel_right_link"/>
    <origin xyz="0.11 -0.1 0.03" rpy="-1.57079 0 0"/>
    <axis xyz="0 0 1"/>
  </joint>

  <link name="wheel_right_link">
    <visual>
      <origin xyz="0 0 0" rpy="0 0 0"/>
      <geometry>
        <cylinder length="0.018" radius="0.03"/>
      </geometry>
      <material name="dark"/>
    </visual>

    <collision>
      <origin xyz="0 0 0" rpy="0 0 0"/>
      <geometry>
        <cylinder length="0.018" radius="0.03"/>
      </geometry>
    </collision>

    <inertial>
      <origin xyz="0 0 0" />
      <mass value="2.8498940e-02" />
      <inertia ixx="1.1175580e-05" ixy="-4.2369783e-11" ixz="-5.9381719e-09"
               iyy="1.1192413e-05" iyz="-1.4400107e-11"
               izz="2.0712558e-05" />
      </inertial>
  </link>

  <joint name="wheel_bleft_joint" type="continuous">
    <parent link="mc_base"/>
    <child link="wheel_bleft_link"/>
    <origin xyz="-0.11 0.1 0.03" rpy="-1.57079 0 0"/>
    <axis xyz="0 0 1"/>
  </joint>

  <link name="wheel_bleft_link">
    <visual>
      <origin xyz="0 0 0" rpy="0 0 0"/>
      <geometry>
        <cylinder length="0.018" radius="0.03"/>
      </geometry>
      <material name="dark"/>
    </visual>

    <collision>
      <origin xyz="0 0 0" rpy="0 0 0"/>
      <geometry>
        <cylinder length="0.018" radius="0.03"/>
      </geometry>
    </collision>

    <inertial>
      <origin xyz="0 0 0" />
      <mass value="2.8498940e-02" />
      <inertia ixx="1.1175580e-05" ixy="-4.2369783e-11" ixz="-5.9381719e-09"
               iyy="1.1192413e-05" iyz="-1.4400107e-11"
               izz="2.0712558e-05" />
      </inertial>
  </link>

  <joint name="wheel_bright_joint" type="continuous">
    <parent link="mc_base"/>
    <child link="wheel_bright_link"/>
    <origin xyz="-0.11 -0.1 0.03" rpy="-1.57079 0 0"/>
    <axis xyz="0 0 1"/>
  </joint>

  <link name="wheel_bright_link">
    <visual>
      <origin xyz="0 0 0" rpy="0 0 0"/>
      <geometry>
        <cylinder length="0.018" radius="0.03"/>
      </geometry>
      <material name="dark"/>
    </visual>

    <collision>
      <origin xyz="0 0 0" rpy="0 0 0"/>
      <geometry>
        <cylinder length="0.018" radius="0.03"/>
      </geometry>
    </collision>

    <inertial>
      <origin xyz="0 0 0" />
      <mass value="2.8498940e-02" />
      <inertia ixx="1.1175580e-05" ixy="-4.2369783e-11" ixz="-5.9381719e-09"
               iyy="1.1192413e-05" iyz="-1.4400107e-11"
               izz="2.0712558e-05" />
      </inertial>
  </link>

  <joint name="rot_joint" type="revolute">
    <parent link="base_footprint"/>
    <child link="rot_link"/>
    <origin xyz="0.067 -0.12 0.278" rpy="0 0 0"/>
    <limit lower="0.0" upper="4.7124" effort="120" velocity="7.5"/>
    <axis xyz="0.0 1.0 0.0"/>
  </joint>

  <link name="rot_link">
    <visual>
    <origin xyz="-0.243 0.238 0.0" rpy="-1.28 0 -1.57079"/>
      <geometry>
        <mesh filename="package://tel_map/meshes/bases/rot.stl" scale="0.001 0.001 0.001"/>
      </geometry>
      <material name="light_black"/>
    </visual>

    <inertial>
      <mass value="0.114" />
      <origin xyz="0 0 0" />
      <inertia ixx="0.001" ixy="0.0" ixz="0.0"
               iyy="0.001" iyz="0.0"
               izz="0.001" />
    </inertial>
  </link>

  <joint name="imu_joint" type="fixed">
    <parent link="mc_base"/>
    <child link="imu_link"/>
    <origin xyz="-0.032 0 0.068" rpy="0 0 0"/>
  </joint>

  <link name="imu_link"/>

  <joint name="scan_joint" type="fixed">
    <parent link="rot_link"/>
    <child link="base_scan"/>
    <origin xyz="0.05 0 0.0" rpy="0 0 0"/>
  </joint>

  <link name="base_scan">

    <visual>
      <origin xyz="-0.038 0.118 0.025" rpy="0 0 0"/>
      <geometry>
        <mesh filename="package://tel_map/meshes/sensors/lds.stl" scale="0.001 0.001 0.001"/>
      </geometry>
      <material name="dark"/>
    </visual>

    <collision>
      <origin xyz="-0.038 0.118 0.025" rpy="0 0 0"/>
      <geometry>
        <cylinder length="0.0315" radius="0.055"/>
      </geometry>
    </collision>

    <inertial>
      <mass value="0.114" />
      <origin xyz="-0.038 0.118 0.025" rpy="0 0 0"/>
      <inertia ixx="0.001" ixy="0.0" ixz="0.0"
               iyy="0.001" iyz="0.0"
               izz="0.001" />
    </inertial>
  </link>

  <joint name="scaner_joint" type="fixed">
    <parent link="base_scan"/>
    <child link="scaner_link"/>
    <origin xyz="-0.038 0.118 0.025" rpy="0 0 0"/>
  </joint>

  <link name="scaner_link"/>

<joint name="cam_yaw_joint" type="revolute">
      <origin xyz="0.0 0.118 -0.05" rpy="0 0 0"/>
      <parent link="rot_link"/>
      <child link="camera_link"/>
      <limit lower="-1.57" upper="1.57" effort="50" velocity="7.5"/>
    	<axis xyz="0.0 0.0 1.0"/>
      <calibration rising="0.0"/>
      <dynamics damping="0.0" friction="0.0"/>
      <safety_controller k_velocity="80" k_position="50" soft_lower_limit="-5.0" soft_upper_limit="5.0" />
    </joint>

  <link name="camera_link">
    <visual>
      <origin xyz="0.0 0.0 0.0" rpy="0 0 0"/>
      <geometry>
        <box size="0.02 0.08 0.02"/>
      </geometry>
      <material name="blue"/>
    </visual>
    <inertial>
      <mass value="0.114" />
      <origin xyz="-0.0 0.0 0.0" rpy="0 0 0"/>
      <inertia ixx="0.001" ixy="0.0" ixz="0.0"
               iyy="0.001" iyz="0.0"
               izz="0.001" />
    </inertial>
  </link>

  <joint name="camera_rgb_joint" type="fixed">
    <origin xyz="0.0 0.0 0.0" rpy="0 0 0"/>
    <parent link="camera_link"/>
    <child link="camera_rgb_frame"/>
  </joint>
  <link name="camera_rgb_frame"/>

  <joint name="camera_rgb_optical_joint" type="fixed">
    <origin xyz="0 0 0" rpy="-1.57 0 -1.57"/>
    <parent link="camera_rgb_frame"/>
    <child link="camera_rgb_optical_frame"/>
  </joint>
  <link name="camera_rgb_optical_frame"/>


<joint name="arm_base_joint" type="fixed">
    <origin xyz="0.12 -0.10 0.075" rpy="0 0 0"/>
    <parent link="base_footprint"/>
    <child link="arm_base"/>
    </joint>

  <link name='arm_base'>
      <inertial>
      <origin xyz="0 0 0" />
      <mass value="0.001" />
      <inertia  ixx="0.0" ixy="0.0"  ixz="0.0"  iyy="0.0"  iyz="0.0"  izz="0.0" />
      </inertial>
      <visual name='visual'>
      <origin xyz="0 0 0"/>
        <geometry>
        <box size="0.04 0.015 0.025" />
        </geometry>
      </visual>
      <collision name='collision'>
      <origin xyz="0 0 0"/>
        <geometry>
        <box size="0.04 0.015 0.025" />
        </geometry>
      </collision>
    </link>

<joint name="plate_joint" type="revolute">
    <origin xyz="0 0 0.064" rpy="0 0 0"/>
      <parent link="arm_base"/>
      <child link="plate"/>
      <limit lower="-1.57" upper="1.57" effort="50" velocity="7.5"/>
    	<axis xyz="0.0 0.0 1.0"/>
      <calibration rising="0.0"/>
      <dynamics damping="0.0" friction="0.0"/>
      <safety_controller k_velocity="80" k_position="50" soft_lower_limit="-5.0" soft_upper_limit="5.0" />
    </joint>

<link name='plate'>
      <inertial>
      <origin xyz="0 0 0.0" />
      <mass value="0.001" />
      <inertia  ixx="0.0" ixy="0.0"  ixz="0.0"  iyy="0.0"  iyz="0.0"  izz="0.0" />
      </inertial>
      <visual name='visual'>
      <origin xyz="0 0 0.0"/>
        <geometry>
        <box size="0.04 0.04 0.025" />
        </geometry>
      </visual>
      <collision name='collision'>
      <origin xyz="0 0 0.0"/>
        <geometry>
        <box size="0.04 0.04 0.025" />
        </geometry>
      </collision>
    </link>

<joint name="j1_joint" type="revolute">
    <origin xyz="0 0 0.0" rpy="0 0 0"/>
      <parent link="plate"/>
      <child link="link2"/>
      <limit lower="-1.57" upper="1.57" effort="50" velocity="7.5"/>
    	<axis xyz="0.0 1.0 0.0"/>
      <calibration rising="0.0"/>
      <dynamics damping="0.0" friction="0.0"/>
      <safety_controller k_velocity="80" k_position="50" soft_lower_limit="-5.0" soft_upper_limit="5.0" />
    </joint>

<link name='link2'>
      <inertial>
      <origin xyz="0 0 0.05215" />
      <mass value="0.001" />
      <inertia  ixx="0.0" ixy="0.0"  ixz="0.0"  iyy="0.0"  iyz="0.0"  izz="0.0" />
      </inertial>
      <visual name='visual'>
      <origin xyz="0 0 0.05215"/>
        <geometry>
        <box size="0.025 0.0564 0.1043" />
        </geometry>
      </visual>
      <collision name='collision'>
      <origin xyz="0 0 0.05215"/>
        <geometry>
        <box size="0.025 0.0564 0.1043" />
        </geometry>
      </collision>
    </link>


<joint name="j2_joint" type="revolute">
    <origin xyz="0 0 0.1043" rpy="0 0 0.0"/>
      <parent link="link2"/>
      <child link="link3"/>
      <limit lower="-1.57" upper="1.57" effort="50" velocity="7.5"/>
    	<axis xyz="0.0 1.0 0.0"/>
      <calibration rising="0.0"/>
      <dynamics damping="0.0" friction="0.0"/>
      <safety_controller k_velocity="80" k_position="50" soft_lower_limit="-5.0" soft_upper_limit="5.0" />
    </joint>
    
<link name='link3'>
      <inertial>
      <origin xyz="0 0 0.0455" />
      <mass value="0.001" />
      <inertia  ixx="0.0" ixy="0.0"  ixz="0.0"  iyy="0.0"  iyz="0.0"  izz="0.0" />
      </inertial>
      <visual name='visual'>
      <origin xyz="0 0 0.0455"/>
        <geometry>
        <box size="0.025 0.0564 0.091" />
        </geometry>
      </visual>
      <collision name='collision'>
      <origin xyz="0 0 0.0455"/>
        <geometry>
        <box size="0.025 0.0564 0.091" />
        </geometry>
      </collision>
    </link>

<joint name="j3_joint" type="revolute">
    <origin xyz="0 0 0.091" rpy="0 0 0"/>
      <parent link="link3"/>
      <child link="link4"/>
      <limit lower="-1.57" upper="1.57" effort="50" velocity="7.5"/>
    	<axis xyz="0.0 1.0 0.0"/>
      <calibration rising="0.0"/>
      <dynamics damping="0.0" friction="0.0"/>
      <safety_controller k_velocity="80" k_position="50" soft_lower_limit="-5.0" soft_upper_limit="5.0" />
    </joint>

<link name='link4'>
      <inertial>
      <origin xyz="0 0 0.0355" />
      <mass value="0.001" />
      <inertia  ixx="0.0" ixy="0.0"  ixz="0.0"  iyy="0.0"  iyz="0.0"  izz="0.0" />
      </inertial>
      <visual name='visual'>
      <origin xyz="0 0 0.0355"/>
        <geometry>
        <box size="0.025 0.0564 0.071" />
        </geometry>
      </visual>
      <collision name='collision'>
      <origin xyz="0 0 0.0355"/>
        <geometry>
        <box size="0.025 0.0564 0.071" />
        </geometry>
      </collision>
    </link>

    <joint name="j4_joint" type="revolute">
    <origin xyz="0 0 0.071" rpy="0 0 0.0"/>
      <parent link="link4"/>
      <child link="hand"/>
      <limit lower="-1.57" upper="1.57" effort="50" velocity="7.5"/>
    	<axis xyz="0.0 0.0 1.0"/>
      <calibration rising="0.0"/>
      <dynamics damping="0.0" friction="0.0"/>
      <safety_controller k_velocity="80" k_position="50" soft_lower_limit="-5.0" soft_upper_limit="5.0" />
    </joint>
    
  <link name='hand'>
      <inertial>
      <origin xyz="0 0 0.02" />
      <mass value="0.001" />
      <inertia  ixx="0.0" ixy="0.0"  ixz="0.0"  iyy="0.0"  iyz="0.0"  izz="0.0" />
      </inertial>
      <visual name='visual'>
      <origin xyz="0 0 0.02"/>
        <geometry>
        <box size="0.01 0.05 0.04" />
        </geometry>
      </visual>
    </link>

  <joint name="f1_joint" type="prismatic">
    <origin xyz="0 0.032 0.03" rpy="0 0 0"/>
      <parent link="hand"/>
      <child link="finger1"/>
      <limit lower="0.0" upper="0.025" effort="50" velocity="0.1"/>
    	<axis xyz="0.0 -1.0 0.0"/>
  </joint>

  <link name='finger1'>
      <inertial>
      <origin xyz="0 0 0.02" rpy="0 0 0"/>
      <mass value="0.001" />
      <inertia  ixx="0.0" ixy="0.0"  ixz="0.0"  iyy="0.0"  iyz="0.0"  izz="0.0" />
      </inertial>
      <visual name='visual'>
      <origin xyz="0 0 0.02" rpy="0 0 0"/>
        <geometry>
        <box size="0.01 0.01 0.04" />
        </geometry>
      </visual>
      <collision>
      <origin xyz="0 0 0.02" rpy="0 0 0"/>
        <geometry>
        <box size="0.01 0.01 0.04" />
        </geometry>
      </collision>
  </link>

  <joint name="f2_joint" type="prismatic">
    <origin xyz="0 -0.032 0.03" rpy="0 0 0"/>
      <parent link="hand"/>
      <child link="finger2"/>
      <limit lower="0.0" upper="0.025" effort="50" velocity="0.1"/>
    	<axis xyz="0.0 1.0 0.0"/>
  </joint>

  <link name='finger2'>
      <inertial>
      <origin xyz="0 0 0.02" rpy="0 0 0"/>
      <mass value="0.001" />
      <inertia  ixx="0.0" ixy="0.0"  ixz="0.0"  iyy="0.0"  iyz="0.0"  izz="0.0" />
      </inertial>
      <visual name='visual'>
      <origin xyz="0 0 0.02" rpy="0 0 0"/>
        <geometry>
        <box size="0.01 0.01 0.04" />
        </geometry>
      </visual>
      <collision>
      <origin xyz="0 0 0.02" rpy="0 0 0"/>
        <geometry>
        <box size="0.01 0.01 0.04" />
        </geometry>
      </collision>
  </link>
</robot>
